<?xml version="1.0"?>
<robot xmlns:xacro="http://www.ros.org/wiki/xacro">

  <xacro:include filename="$(find mr2_description)/urdf/servo_motors/servo_motors.xacro"/>

  <xacro:macro name="leg1" params="prefix parent *joint_origin">
    <joint name="${prefix}_leg1_joint" type="revolute">
      <xacro:insert_block name="joint_origin"/>
      <axis xyz="0 0 1"/>
      <xacro:KRS4034HVICS_limit/>
      <parent link="${parent}"/>
      <child link="${prefix}_leg1_link"/>
    </joint>

    <link name="${prefix}_leg1_link">
      <visual>
        <origin rpy="0.00000 0.00000 0.00000" xyz="0.00000 0.00000 0.00000"/>
        <geometry>
          <mesh filename="package://mr2_description/meshes/leg1_2.STL"/>
        </geometry>
      </visual>
      <collision>
        <origin rpy="0.00000 0.00000 0.00000" xyz="0.00000 0.00000 0.00000"/>
        <geometry>
          <mesh filename="package://mr2_description/meshes/leg1_2.STL"/>
        </geometry>
      </collision>
      <inertial>
        <origin rpy="-0.14190 2.35619 1.42899" xyz="-0.00006 -0.02500 -0.01987"/>
        <mass value="0.01599"/>
        <inertia 
          ixx="0.00000569169" ixy="0.00000000000" ixz="0.00000000000"
          iyy="0.00000586951" iyz="0.00000000000" 
          izz="0.00000587725"/>
      </inertial>
    </link>
  </xacro:macro>

</robot>
