<?xml version="1.0"?>
<robot xmlns:xacro="http://www.ros.org/wiki/xacro">

  <xacro:include filename="$(find mr2_description)/urdf/servo_motors/servo_motors.xacro"/>

  <xacro:macro name="leg3" params="prefix parent *joint_origin">
    <joint name="${prefix}_leg3_joint" type="revolute">
      <xacro:insert_block name="joint_origin"/>
      <axis xyz="1 0 0"/>
      <xacro:KRS4034HVICS_limit/>
      <parent link="${parent}"/>
      <child link="${prefix}_leg3_link"/>
    </joint>

    <link name="${prefix}_leg3_link">
      <visual>
        <origin rpy="0.00000 0.00000 0.00000" xyz="0.00000 0.00000 0.00000"/>
        <geometry>
          <mesh filename="package://mr2_description/meshes/leg3_2.STL"/>
        </geometry>
      </visual>
      <collision>
        <origin rpy="0.00000 0.00000 0.00000" xyz="0.00000 0.00000 0.00000"/>
        <geometry>
          <mesh filename="package://mr2_description/meshes/leg3_2.STL"/>
        </geometry>
      </collision>
      <inertial>
        <origin rpy="0.00000 1.59079 -1.57079" xyz="0.01987 0.00114 0.14678"/>
        <mass value="0.13257"/>
        <inertia
          ixx="0.00004387620" ixy="0.00000000000" ixz="0.00000000000"
          iyy="0.00059834039" iyz="0.00000000000"
          izz="0.00062747138"/>
      </inertial>
    </link>
  </xacro:macro>

</robot>
